- [8.1 错误处理](#81-错误处理)
  - [8.1.1 try](#811-try)
  - [8.1.2 调用栈](#812-调用栈)
  - [8.1.3 记录错误](#813-记录错误)
  - [8.1.3 抛出错误](#813-抛出错误)
- [8.2 调试](#82-调试)
  - [8.2.1 断言](#821-断言)
  - [8.2.2 日志](#822-日志)
  - [8.2.3 pdb](#823-pdb)
  - [8.2.4 `pdb.set_trace()`](#824-pdbset_trace)
  - [8.2.5 使用 IDE 调试](#825-使用-ide-调试)
- [8.3 单元测试](#83-单元测试)
  - [8.3.1 unittest](#831-unittest)
  - [8.3.2 setUp与tearDown](#832-setup与teardown)
- [8.4 文档测试](#84-文档测试)

## 8.1 错误处理

### 8.1.1 try

```python
try:
    print("try...")
    r = 10 / 0
    print("r = ", r)
except ZeroDivisionError as e:
    print("except:",e)
finally:
    print("finaly...")
print("END")
```

如果执行出错，则后续代码不会继续执行，而是直接跳转至错误处理代码，即except语句块，执行完except后，如果有finally语句块，则执行finally语句块，至此，执行完毕。

没有错误发生，所以except语句块不会被执行，但是finally如果有，则一定会被执行（可以没有finally语句）。

多个except来捕获不同类型的错误：

```python
try:
    print('try...')
    r = 10 / int('a')
    print('result:', r)
except ValueError as e:
    print('ValueError:', e)
except ZeroDivisionError as e:
    print('ZeroDivisionError:', e)
finally:
    print('finally...')
print('END')
```

如果没有错误发生，可以在except语句块后面加一个else，当没有错误发生时，会自动执行else语句：

```python
try:
    print('try...')
    r = 10 / int('2')
    print('result:', r)
except ValueError as e:
    print('ValueError:', e)
except ZeroDivisionError as e:
    print('ZeroDivisionError:', e)
else:
    print('no error!')
finally:
    print('finally...')
print('END')
```

Python的错误其实也是class，所有的错误类型都继承自BaseException，所以在使用except时需要注意的是，它不但捕获该类型的错误，还把其子类的错误也一起捕获。

Python所有的错误都是从BaseException类派生的。

使用try...except捕获错误还有一个巨大的好处，就是可以跨越多层调用，

不需要在每个可能出错的地方去捕获错误，只要在合适的层次去捕获错误就可以了。

### 8.1.2 调用栈

如果错误没有被捕获，它就会一直往上抛，最后被Python解释器捕获。

出错的时候，一定要分析错误的调用栈信息，才能定位错误的位置。

### 8.1.3 记录错误

如果不捕获错误，自然可以让Python解释器来打印出错误堆栈，但程序也被结束了。

既然我们能捕获错误，就可以把错误堆栈打印出来，然后分析错误原因，同时，**让程序继续执行下去**。

```python
import logging

logging.basicConfig(level=logging.DEBUG,
                    # filename='output.log',
                    format='%(asctime)s - %(name)s - %(levelname)s - %(lineno)d - %(module)s - %(message)s')
logger = logging.getLogger(__name__)

logger.info('This is a log info')
logger.debug('Debugging')
logger.warning('Warning exists')
logger.info('Finish')
```

logger 和 logging 的区别：logger 会显示是哪个模块的消息。

| level | 用法 |
|:---: | :---: |
| DEBUG | 调试需要的详细信息|
|INFO | 确认程序正常工作|
|WARNING |程序仍旧正常工作，但是报警未来可能出现的问题（如空间不够） |
|ERROR | 程序某些功能不能继续运行|
| CRITICAL | 非常严重的错误，程序无法继续运行 |


```python
import logging

def foo(s):
    return 10 / int(s)

def bar(s):
    return foo(s) * 2

def main():
    try:
        bar('0')
    except Exception as e:
        logging.exception(e)

main()
print('END')
```

### 8.1.3 抛出错误

因为错误是class，捕获一个错误就是捕获到该class的一个实例。因此，错误并不是凭空产生的，而是有意创建并抛出的。Python的内置函数会抛出很多类型的错误，我们自己编写的函数也可以抛出错误。

如果要抛出错误，首先根据需要，可以定义一个错误的class，选择好继承关系，然后，用raise语句抛出一个错误的实例：

```python
import logging


class FooError(ValueError):
    pass

def foo(s):
    n = int(s)
    if n==0:
        raise FooError('invalid value: %s' % s)
    return 10 / n

try:
    foo('0')
except Exception as e:
    logging.exception(e)
```

只有在必要的时候才定义我们自己的错误类型。如果可以选择Python已有的内置的错误类型（比如ValueError，TypeError），尽量使用Python内置的错误类型。

还有一种错误处理方式：由于当前函数不知道应该怎么处理该错误，继续往上抛，让顶层调用者去处理：

```python
def foo(s):
    n = int(s)
    if n==0:
        raise ValueError('invalid value: %s' % s)
    return 10 / n

def bar():
    try:
        foo('0')
    except ValueError as e:
        print('ValueError!')
        raise

bar()
```

raise语句如果不带参数，就会把当前错误原样抛出。此外，在except中raise一个Error，还可以把一种类型的错误转化成另一种类型：

```python
try:
    10 / 0
except ZeroDivisionError:
    raise ValueError('input error!')
```

最后一个except子句可以忽略异常的名称，它将被当作通配符使用。你可以使用这种方法打印一个错误信息，然后再次把异常抛出。

```python
import sys

try:
    f = open('myfile.txt')
    s = f.readline()
    i = int(s.strip())
except OSError as err:
    print("OS error: {0}".format(err))
except ValueError:
    print("Could not convert data to an integer.")
except:
    print("Unexpected error:", sys.exc_info()[0])
    raise
```

## 8.2 调试

### 8.2.1 断言

```python
def foo(s):
    n = int(s)
    assert n != 0, 'n is zero!'
    return 10 / n

def main():
    foo('0')
```

assert的意思是，表达式 `n != 0` 应该是 `True` ，否则，根据程序运行的逻辑，后面的代码肯定会出错。

如果断言失败，assert语句本身就会抛出 `AssertionError` 。

启动Python解释器时可以用 `-O`参数来关闭assert：

```shell
python -O err.py
```

断言的开关“-O”是英文大写字母O，不是数字0，关闭后，可以把所有的assert语句当成pass来看。

### 8.2.2 日志


```python
import logging

logging.basicConfig(level=logging.DEBUG,
                    # filename='output.log',
                    format='%(asctime)s - %(name)s - %(levelname)s - %(lineno)d - %(module)s - %(message)s')
logger = logging.getLogger(__name__)

logger.info('This is a log info')
logger.debug('Debugging')
logger.warning('Warning exists')
logger.info('Finish')
```

### 8.2.3 pdb

启动 pdb：

```python
python3 -m pdb xxx.py
```

n -- next 单步执行
l -- list 列出代码
ll -- 列出所有代码
b lineno
b filename:lineno 
b functionname
p 变量名 -- print 打印变量
q - 退出调试
cl 清除所有断点
cl filename:lineno - 清除断点
cl bpnumber
s - 单步执行，进入函数体。
c - 继续执行，直到遇到断点。

### 8.2.4 `pdb.set_trace()`

使用 pdb.set_trace() 设置断点。

```python
# err.py
import pdb

s = '0'
n = int(s)
pdb.set_trace() # 运行到这里会自动暂停
print(10 / n)
```

运行代码，程序会自动在pdb.set_trace()暂停并进入pdb调试环境，可以用命令p查看变量，或者用命令 `c` 继续运行。

### 8.2.5 使用 IDE 调试

vscode、pycharm 等。

## 8.3 单元测试

### 8.3.1 unittest

为了编写单元测试，我们需要引入Python自带的unittest模块。

编写单元测试时，我们需要编写一个测试类，从`unittest.TestCase`继承。

以test开头的方法就是测试方法，不以test开头的方法不被认为是测试方法，测试的时候不会被执行。

对每一类测试都需要编写一个test_xxx()方法。由于`unittest.TestCase`提供了很多内置的条件判断，我们只需要调用这些方法就可以断言输出是否是我们所期望的。最常用的断言就是assertEqual()：

`self.assertEqual(abs(-1), 1) # 断言函数返回的结果与1相等`

另一种重要的断言就是期待抛出指定类型的Error，比如通过`d['empty']`访问不存在的key时，断言会抛出KeyError：

```python
with self.assertRaises(KeyError):
    value = d['empty']
```

而通过d.empty访问不存在的key时，我们期待抛出AttributeError：

```python
with self.assertRaises(AttributeError):
    value = d.empty
```

运行单元测试：

`python -m unittest mydict_test`

这是推荐的做法，因为这样可以一次批量运行很多单元测试。


```python
class Dict(dict):

    def __init__(self, **kw):
        super().__init__(**kw)

    def __getattr__(self, key):
        try:
            return self[key]
        except KeyError:
            raise AttributeError(r"'Dict' object has no attribute '%s'" % key)

    def __setattr__(self, key, value):
        self[key] = value
```

```python
import unittest

from mydict import Dict

class TestDict(unittest.TestCase):

    def test_init(self):
        d = Dict(a=1, b='test')
        self.assertEqual(d.a, 1)
        self.assertEqual(d.b, 'test')
        self.assertTrue(isinstance(d, dict))

    def test_key(self):
        d = Dict()
        d['key'] = 'value'
        self.assertEqual(d.key, 'value')

    def test_attr(self):
        d = Dict()
        d.key = 'value'
        self.assertTrue('key' in d)
        self.assertEqual(d['key'], 'value')

    def test_keyerror(self):
        d = Dict()
        with self.assertRaises(KeyError):
            value = d['empty']

    def test_attrerror(self):
        d = Dict()
        with self.assertRaises(AttributeError):
            value = d.empty
```

### 8.3.2 setUp与tearDown

可以在单元测试中编写两个特殊的setUp()和tearDown()方法。这两个方法会分别在每调用一个测试方法的前后分别被执行。

```python
class TestDict(unittest.TestCase):

    def setUp(self):
        print('setUp...')

    def tearDown(self):
        print('tearDown...')
```

单元测试可以有效地测试某个程序模块的行为，是未来重构代码的信心保证。

单元测试的测试用例要覆盖常用的输入组合、边界条件和异常。

单元测试代码要非常简单，如果测试代码太复杂，那么测试代码本身就可能有bug。

单元测试通过了并不意味着程序就没有bug了，但是不通过程序肯定有bug。

## 8.4 文档测试

轻量级的单元测试。

Python内置的“文档测试”（doctest）模块可以直接提取注释中的代码并执行测试。

doctest严格按照Python交互式命令行的输入和输出来判断测试结果是否正确。有测试异常的时候，可以用...表示中间一大段烦人的输出。

doctest是python自带的一个模块。doctest有两种使用方式：一种是嵌入到python源码中，另外一种是放到一个独立文件。

doctest模块会搜索那些看起来像是python交互式会话中的代码片段，然后尝试执行并验证结果。

```python
def abs(n):
    '''
    Function to get absolute value of number.
    
    Example:
    
    >>> abs(1)
    1
    >>> abs(-1)
    1
    >>> abs(0)
    0
    '''
    return n if n >= 0 else (-n)
```

```python
class Dict(dict):
    '''
    Simple dict but also support access as x.y style.

    >>> d1 = Dict()
    >>> d1['x'] = 100
    >>> d1.x
    100
    >>> d1.y = 200
    >>> d1['y']
    200
    >>> d2 = Dict(a=1, b=2, c='3')
    >>> d2.c
    '3'
    >>> d2['empty']
    Traceback (most recent call last):
        ...
    KeyError: 'empty'
    >>> d2.empty
    Traceback (most recent call last):
        ...
    AttributeError: 'Dict' object has no attribute 'empty'
    '''
    def __init__(self, **kw):
        super(Dict, self).__init__(**kw)

    def __getattr__(self, key):
        try:
            return self[key]
        except KeyError:
            raise AttributeError(r"'Dict' object has no attribute '%s'" % key)

    def __setattr__(self, key, value):
        self[key] = value

if __name__=='__main__':
    import doctest
    doctest.testmod()
```